<?xml version="1.0"?>
<robot xmlns:xacro="http://www.ros.org/wiki/xacro"  name="robot">

    <xacro:include filename="inertial_macros.xacro" />

    <material name="white">
        <color rgba="1 1 1 1"/>
    </material>

    <material name="orange">
        <color rgba="1 0.3 0.1 1"/>
    </material>

    <material name="blue">
        <color rgba="0.2 0.2 1 1"/>
    </material>

    <material name="black">
        <color rgba="0 0 0 1"/>
    </material>

    <material name="red">
        <color rgba="1 0 0 1"/>
    </material>

    <link name="base_link">
    </link>

   <!-- Wheelbase -->

    <joint name="wheelbase_joint" type="fixed">
        <parent link="base_link"/>
        <child link="wheelbase"/>
        <origin xyz="0 0 0.0121"/>
    </joint>

    <link name="wheelbase">
        <visual>
            <origin xyz="0 0 0" rpy="0 0 0"/>
            <geometry>
                <box size="0.075 0.24 0.046"/>
            </geometry>
            <material name="black"/>
        </visual>
        <collision>
            <origin xyz="0 0 0" rpy="0 0 0"/>
            <geometry>
                <box size="0.075 0.24 0.046"/>
            </geometry>
        </collision>
        <xacro:inertial_box mass="0.5" x="0.075" y="0.24" z="0.046">
            <origin xyz="0 0 0" rpy="0 0 0"/>
        </xacro:inertial_box>
    </link>

    <gazebo reference="wheelbase">
        <material>Gazebo/Black</material>
    </gazebo>

    <!-- CHASSIS -->

    <joint name="chassis_joint" type="fixed">
        <parent link="wheelbase"/>
        <child link="chassis"/>
        <origin xyz="-0.0725 0 0.02685"/>
    </joint>

    <link name="chassis">
        <visual>
            <origin xyz="0 0 0" rpy="0 0 0"/>
            <geometry>
                <box size="0.33 0.24 0.0077"/>
            </geometry>
            <material name="orange"/>
        </visual>
        <collision>
            <origin xyz="0 0 0" rpy="0 0 0"/>
            <geometry>
                <box size="0.33 0.24 0.0077"/>
            </geometry>
        </collision>
        <xacro:inertial_box mass="1.027" x="0.33" y="0.24" z="0.0077">
            <origin xyz="0 0 0" rpy="0 0 0"/>
        </xacro:inertial_box>
    </link>

    <gazebo reference="chassis">
        <material>Gazebo/Orange</material>
    </gazebo>

    <!-- RIGHT WHEEL -->

    <joint name="right_wheel_joint" type="continuous">
        <parent link="base_link"/>
        <child link="right_wheel"/>
        <origin xyz="0 -0.1425 0" rpy="${pi/2} 0 0"/>
        <axis xyz="0 0 -1"/>
    </joint>

    <link name="right_wheel">
        <visual>
            <origin xyz="0 0 0" rpy="0 0 0"/>
            <geometry>
                <cylinder length="0.0265" radius="0.0495" />
            </geometry>
        <material name="white"/>
        </visual>
        <collision>
            <geometry>
                <cylinder length="0.0265" radius="0.0495" />
            </geometry>
        </collision>
        <xacro:inertial_cylinder mass="0.134" length="0.0265" radius="0.0495">
            <origin xyz="0 0 0" rpy="0 0 0"/>
        </xacro:inertial_cylinder>
    </link>

    <gazebo reference="right_wheel">
        <material>Gazebo/White</material>
    </gazebo>

	<!-- LEFT WHEEL -->
    <joint name="left_wheel_joint" type="continuous">
        <parent link="base_link"/>
        <child link="left_wheel"/>
        <origin xyz="0 0.1425 0" rpy="${pi/2} 0 0"/>
        <axis xyz="0 0 1"/>
    </joint>

    <link name="left_wheel">
        <visual>
            <origin xyz="0 0 0" rpy="0 0 0"/>
            <geometry>
                <cylinder length="0.0265" radius="0.0495" />
            </geometry>
        <material name="white"/>
        </visual>
        <collision>
            <geometry>
                <cylinder length="0.0265" radius="0.0495" />
            </geometry>
        </collision>
        <xacro:inertial_cylinder mass="0.134" length="0.0265" radius="0.0495">
            <origin xyz="0 0 0" rpy="0 0 0"/>
        </xacro:inertial_cylinder>
    </link>

    <gazebo reference="left_wheel">
        <material>Gazebo/White</material>
    </gazebo>


    <!-- CASTER WHEEL -->

    <joint name="caster_wheel_joint" type="fixed">
        <parent link="base_link"/>
        <child link="caster_wheel"/>
        <origin xyz="-0.18 0 0" rpy="0 0 0"/>
    </joint>

    <link name="caster_wheel">
        <visual>
            <geometry>
                <sphere radius="0.0495" />
            </geometry>
            <material name="black"/>
        </visual>
        <collision>
            <geometry>
                <sphere radius="0.0495" />
            </geometry>
        </collision>
        <xacro:inertial_sphere mass="0.2" radius="0.0495">
            <origin xyz="0 0 0" rpy="0 0 0"/>
        </xacro:inertial_sphere>
    </link>

    <gazebo reference="caster_wheel">
        <material>Gazebo/Black</material>
        <mu1 value="0.001"/>
        <mu2 value="0.001"/>
    </gazebo>

</robot>
